Workbook
Name ____MST2: [1]Sheet1!#REF!
Name ___12_Expediting_function_ver2_0_: #REF!
Name ___12_Expediting_function_ver2_0__BEST: #REF!
Name ___13_ALL_back_order_with_VOH__ALL__add_vendor: #REF!
Name ___13_ALL_back_order_with_VOH__ALL__BEST: #REF!
Name ___2_Order_Status_Report__OSR_: #REF!
Name ___6_VOR_for_P_Wirote_ver2_0_: #REF!
Name ___MST2: [2]Sheet1!#REF!
Name __1_Vendor_Order_Release___Expediting: #REF!
Name __12_Expediting_function_ver2_0_: #REF!
Name __12_Expediting_function_ver2_0__BEST: #REF!
Name __13_ALL_back_order_with_VOH__ALL__add_vendor: #REF!
Name __13_ALL_back_order_with_VOH__ALL__BEST: #REF!
Name __2_Order_Status_Report__OSR_: #REF!
Name __6_VOR_for_P_Wirote_ver2_0_: #REF!
Name __MST2: [2]Sheet1!#REF!
Name __VOR_for_P_Wirote_ver2_0_: #REF!
Name _1_1_Vendor_Order_Release___Expediting: #REF!
Name _1_Vendor_Order_Release___Expediting: #REF!
Name _15_Vendor_code___names: #REF!
Name _2_12_Expediting_function_ver2_0_: #REF!
Name _3_12_Expediting_function_ver2_0__BEST: #REF!
Name _４．設計製作TYPE1: #REF!
Name _4_13_ALL_back_order_with_VOH__ALL__add_vendor: #REF!
Name _５．保証TYPE1: #REF!
Name _5_13_ALL_back_order_with_VOH__ALL__BEST: #REF!
Name _６．納入TYPE1: #REF!
Name _6_2_Order_Status_Report__OSR_: #REF!
Name _７．その他諸仕様TYPE1: #REF!
Name _7_6_VOR_for_P_Wirote_ver2_0_: #REF!
Name _8_715_Vendor_code___names: #REF!
Name _MST2: [14]Sheet1!#REF!
Name a: #REF!
Name A4_2_Order_Status_Report__OSR_: #REF!
Name APPLY: #REF!
Name APPLY_DUMMY: #REF!
Name AverageRange104: [17]SpecUM47RAA!$G$104,[17]SpecUM47RAA!$E$104
Name AverageRange105: [17]SpecUM47RAA!$G$105,[17]SpecUM47RAA!$E$105
Name AverageRange118: [17]SpecUM47RAA!$G$118,[17]SpecUM47RAA!$E$118
Name AverageRange119: [17]SpecUM47RAA!$G$119,[17]SpecUM47RAA!$E$119
Name AverageRange8: [17]SpecUM47RAA!$G$8,[17]SpecUM47RAA!$E$8
Name BBB: '[18]DM forecast'!#REF!
Name CAX_0426: #REF!
Name clratio: '[18]DM forecast'!#REF!
Name coefficient: [19]SUM14ZC1!#REF!
Name ColumnTitle1: #REF!
Name edratio: '[18]DM forecast'!#REF!
Name ff: [14]Sheet1!#REF!
Name FST: #REF!
Name Hoong_Order_Sheet_calculate_FC: #REF!
Name Hoong_Order_Sheet_run_top_amount: #REF!
Name Hoong_Order_Sheet_TRY_NEW: #REF!
Name M1_Inventory_and_Month_Do: #REF!
Name ModelMaster: #REF!
Name MPA: #REF!
Name msc: #REF!
Name MST: [1]Sheet1!#REF!
Name P_Gr: #REF!
Name PaintBS: #REF!
Name PaintJM: #REF!

Sheet DN
G2: KOCH PACKAGING AND PACKING SERVICES
D4: Delivery Note | O4: ปริ้น 2 copy
O5: เย็บติดกับ บิลซัพ
C6: Supplier code : | E6: KT076 | G6: Invoice No : | H6: 11726091882 | K6: DN No. : | L6: DN2610070001
C8: Supplier name : | E8: THAI KOITO CO.,LTD. | J8: Delivery Date : | L8: =TODAY() -> 46302
B11: No. | C11: PO. No. | D11: Line | E11: Part No. | F11: Supplier Part No. | H11: Part Name | I11: Invoice QTY. | J11: Dom QTY. | K11: Exp QTY. | L11: Remark
B12: 1 | C12: 229530 | D12: 2 | E12: D09K51160D | H12: LAMP(L),RR COMB. | I12: 35 | J12: 35
B13: 2 | C13: 229530 | D13: 4 | E13: DA6A513F0B | H13: LAMP(R),TRUNK LID | I13: 30 | J13: 30
B14: 3 | C14: 229530 | D14: 3 | E14: D43N51160B | H14: LAMP(L),RR COMB. | I14: 15 | J14: 15
B15: 4 | C15: 229530 | D15: 1 | E15: D09K51150D | H15: LAMP(R),RR COMB. | I15: 45 | J15: 45
B16: 5 | C16: 229530 | D16: 5 | E16: DA6A513G0B | H16: LAMP(L),TRUNK LID | I16: 30 | J16: 30
B17: 6 | C17: 229530 | D17: 6 | E17: DB7A51150B | H17: LAMP(R),RR COMB. | I17: 170 | J17: 170
B18: 7 | C18: 229530 | D18: 11 | E18: DB7A513J8 | H18: GASKET(L),LAMP-TRUNK | I18: 20 | J18: 20
B19: 8 | C19: 229530 | D19: 8 | E19: DB7A513F0C | H19: LAMP(R),TRUNK LID | I19: 130 | J19: 130
B20: 9 | C20: 229530 | D20: 7 | E20: DB7A51153 | H20: GASKET(R),RR.COMB. | I20: 15 | J20: 15
B21: 10 | C21: 229530 | D21: 9 | E21: DB7A513G0C | H21: LAMP(L),TRUNK LID | I21: 110 | J21: 110
B22: 11 | C22: 229530 | D22: 10 | E22: DB7A513H8 | H22: GASKET(R),LAMP-TRUNK | I22: 15 | J22: 15
B23: 12 | C23: 229530 | D23: 17 | E23: UC2B51250B | H23: LAMP(L),BACK UP | I23: 125 | J23: 125
... B41: 30 | C41: 229530 | D41: 28 | E41: UM4751070A | H41: LAMP(L),FRT. COMB. | I41: 5 | J41: 5
H43: Total : | I43: =SUM(I12:I41) -> 1502 | J43: =SUM(J12:J41) -> 1502
C46: ลงชื่อผู้ออกเอกสาร | F46: ลงชื่อผู้รับสินค้า
C48: (______________________) | F48: (______________________)
C49: KOCH | F49: MLYA

Sheet DeliveryTripSheet Lamp
G2: KOCH PACKAGING AND PACKING SERVICES
C6: Shipper : KOCH | E6: Ship Date : | G6: =TODAY() -> 46302 | I6: Invoice No. : | K6: =DN!H6 -> 11726091882
C8: Ship To : Mazda (MST) | E8: Trip Number : | G8: 1
I9: Supplier Name: | K9: THAI KOITO CO.,LTD.
C10: Trip Sheet Number : | E10: MST_20261007-001 | P10: ปริ้น 2 copy
B13: No. | C13: Invoice No. | D13: Po No. | E13: Line | F13: Part No. | G13: Part Name | I13: QTY | K13: Delivery Note | L13: Rack No. | N13: Remark
B14: 1 | C14: 11726091882 | D14: 229530 | E14: 6 | F14: DB7A51150B | G14: LAMP(R),RR COMB. | I14: 21 | K14: DN2610070001 | L14: 8B5
B15: 2 | C15: 11726091882 | D15: 229530 | E15: 19 | F15: UC2J510K0B | G15: UNIT(R),HEAD LAMP | I15: 12 | K15: DN2610070001 | L15: 8B5
B16: 3 | C16: 11726091882 | D16: 229530 | E16: 4 | F16: DA6A513F0B | G16: LAMP(R),TRUNK LID | I16: 30 | K16: DN2610070001 | L16: 8B5
B17: 4 | C17: 11726091882 | D17: 229530 | E17: 3 | F17: D43N51160B | G17: LAMP(L),RR COMB. | I17: 15 | K17: DN2610070001 | L17: 8B5
B18: 5 | C18: 11726091882 | D18: 229530 | E18: 3 | F18: UL4H510K0B | G18: UNIT(R),HEAD LAMP | I18: 2 | K18: DN2610070001 | L18: 8B5
B19: 6 | C19: 11726091882 | D19: 229530 | E19: 26 | F19: UL4M510K0B | G19: UNIT(R),HEAD LAMP | I19: 12 | K19: DN2610070001 | L19: 8B5
B20: 7 | C20: 11726091882 | D20: 229530 | E20: 6 | F20: DB7A51150B | G20: LAMP(R),RR COMB. | I20: 21 | K20: DN2610070001 | L20: 8B5
B21: 8 | C21: 11726091882 | D21: 229530 | E21: 6 | F21: DB7A51150B | G21: LAMP(R),RR COMB. | I21: 21 | K21: DN2610070001 | L21: 8B5
B22: 9 | C22: 11726091882 | D22: 229530 | E22: 23 | F22: UL4J51160A | G22: LAMP(L),RR COMB. | I22: 33 | K22: DN2610070001 | L22: 8B5
B23: 10 | C23: 11726091882 | D23: 229530 | E23: 17 | F23: UC2B51250B | G23: LAMP(L),BACK UP | I23: 96 | K23: DN2610070001 | L23: 8B5
B24: 11 | C24: 11726091882 | D24: 229530 | E24: 25 | F24: UL4L510K0B | G24: UNIT(R),HEAD LAMP | I24: 12 | K24: DN2610070001 | L24: 8B5
B25: 12 | C25: 11726091882 | D25: 229530 | E25: 17 | F25: UC2B51250B | G25: LAMP(L),BACK UP | I25: 29 | K25: DN2610070001 | L25: 8B5
... B76: 63 | C76: 11726091882 | D76: 229530 | E76: 12 | F76: DN2151680A | G76: LAMP(R),F.FOG | I76: 20 | K76: DN2610070001 | L76: 8B5
B77: Total : | I77: =SUM(I14:I76) -> 1502
B80: KOCH Team | G80: Transport Team | K80: MLYA Team
B81: Shipper Name : | G81: Driver Name : | K81: Recipient Name :
B82: Time : | G82: Truck No : | K82: Time :
B83: Delivery Date : | G83: Receive Date : | K83: Receive Date :
B86: Remark :

Sheet 1
F2: KOCH PACKAGING AND PACKING SERVICES
D4: Package Label
D6: Shipper : | E6: KOCH | F6: Ship To : | G6: Mazda (MST) | H6: Package No. : | J6: =D14&"-"&E14&"-"&"001" -> 229530-6-001
C8: Supplier Code : | E8: KT076 | F8: Invoice No. : | G8: ='DeliveryTripSheet Lamp'!C14 -> 11726091882
C10: Supplier Name: | E10: THAI KOITO CO.,LTD.
B13: No. | C13: Rack No. | D13: PO. No. | E13: Line | F13: Part No. | G13: Part Name | H13: Invoice QTY. | I13: Dom QTY. | J13: Exp QTY. | K13: Delivery QTY | L13: Remark
B14: 1 | C14: 201 | D14: 229530 | E14: 6 | F14: DB7A51150B | G14: LAMP(R),RR COMB. | H14: 21 | I14: =H14 -> 21 | J14: 0 | K14: =I14 -> 21 | L14: ="8B5"&"/"&C14 -> 8B5/201
B22: Total | K22: =SUM(K14:K21) -> 21
C24: ลงชื่อผู้ออกเอกสาร
C26: (______________________)
C27: KOCH

Sheet 2
F2: KOCH PACKAGING AND PACKING SERVICES
D4: Package Label
D6: Shipper : | E6: KOCH | F6: Ship To : | G6: Mazda (MST) | H6: Package No. : | J6: =D14&"-"&E14&"-"&"001" -> 229530-19-001
C8: Supplier Code : | E8: KT076 | F8: Invoice No. : | G8: ='1'!G8 -> 11726091882
C10: Supplier Name: | E10: THAI KOITO CO.,LTD.
B13: No. | C13: Rack No | D13: PO. No. | E13: Line | F13: Part No. | G13: Part Name | H13: Invoice QTY. | I13: Dom QTY. | J13: Exp QTY. | K13: Delivery QTY | L13: Remark
B14: 1 | C14: 290 | D14: 229530 | E14: 19 | F14: UC2J510K0B | G14: UNIT(R),HEAD LAMP | H14: 12 | I14: =H14 -> 12 | K14: =I14 -> 12 | L14: ="8B5"&"/"&C14 -> 8B5/290
B31: Total | K31: =SUM(K14:K30) -> 12
C33: ลงชื่อผู้ออกเอกสาร
C35: (______________________)
C36: KOCH

Sheet 3
F2: KOCH PACKAGING AND PACKING SERVICES
D4: Package Label
D6: Shipper : | E6: KOCH | F6: Ship To : | G6: Mazda (MST) | H6: Package No. : | J6: =D14&"-"&E14&"-"&"001" -> 229530-4-001
C8: Supplier Code : | E8: KT076 | F8: Invoice No. : | G8: ='2'!G8 -> 11726091882
C10: Supplier Name: | E10: THAI KOITO CO.,LTD.
B13: No. | C13: Rack No | D13: PO. No. | E13: Line | F13: Part No. | G13: Part Name | H13: Invoice QTY. | I13: Dom QTY. | J13: Exp QTY. | K13: Delivery QTY | L13: Remark
B14: 1 | C14: 296 | D14: 229530 | E14: 4 | F14: DA6A513F0B | G14: LAMP(R),TRUNK LID | H14: 30 | I14: =H14 -> 30 | K14: =I14 -> 30 | L14: ="8B5"&"/"&C14 -> 8B5/296
B15: 2 | C15: 296 | D15: 229530 | E15: 3 | F15: D43N51160B | G15: LAMP(L),RR COMB. | H15: 15 | I15: =H15 -> 15 | K15: =I15 -> 15 | L15: ="8B5"&"/"&C15 -> 8B5/296
B16: 3 | C16: 296 | D16: 229530 | E16: 3 | F16: UL4H510K0B | G16: UNIT(R),HEAD LAMP | H16: 2 | I16: =H16 -> 2 | K16: =I16 -> 2 | L16: ="8B5"&"/"&C16 -> 8B5/296
B22: Total | K22: =SUM(K14:K21) -> 47
C24: ลงชื่อผู้ออกเอกสาร
C26: (______________________)
C27: KOCH

Sheet 4
F2: KOCH PACKAGING AND PACKING SERVICES
D4: Package Label
D6: Shipper : | E6: KOCH | F6: Ship To : | G6: Mazda (MST) | H6: Package No. : | J6: =D14&"-"&E14&"-"&"001" -> 229530-26-001
C8: Supplier Code : | E8: KT076 | F8: Invoice No. : | G8: ='3'!G8 -> 11726091882
C10: Supplier Name: | E10: THAI KOITO CO.,LTD.
B13: No. | C13: Rack No | D13: PO. No. | E13: Line | F13: Part No. | G13: Part Name | H13: Invoice QTY. | I13: Dom QTY. | J13: Exp QTY. | K13: Delivery QTY | L13: Remark
B14: 1 | C14: 297 | D14: 229530 | E14: 26 | F14: UL4M510K0B | G14: UNIT(R),HEAD LAMP | H14: 12 | I14: =H14 -> 12 | K14: =I14 -> 12 | L14: ="8B5"&"/"&C14 -> 8B5/297
B22: Total | K22: =SUM(K14:K21) -> 12
C24: ลงชื่อผู้ออกเอกสาร
C26: (______________________)
C27: KOCH

Sheet 5
F2: KOCH PACKAGING AND PACKING SERVICES
D4: Package Label
D6: Shipper : | E6: KOCH | F6: Ship To : | G6: Mazda (MST) | H6: Package No. : | J6: =D14&"-"&E14&"-"&"001" -> 229530-6-001
C8: Supplier Code : | E8: KT076 | F8: Invoice No. : | G8: ='4'!G8 -> 11726091882
C10: Supplier Name: | E10: THAI KOITO CO.,LTD.
B13: No. | C13: Rack No | D13: PO. No. | E13: Line | F13: Part No. | G13: Part Name | H13: Invoice QTY. | I13: Dom QTY. | J13: Exp QTY. | K13: Delivery QTY | L13: Remark
B14: 1 | C14: 362 | D14: 229530 | E14: 6 | F14: DB7A51150B | G14: LAMP(R),RR COMB. | H14: 21 | I14: =H14 -> 21 | K14: =I14 -> 21 | L14: ="8B5"&"/"&C14 -> 8B5/362
B22: Total | K22: =SUM(K14:K21) -> 21
C24: ลงชื่อผู้ออกเอกสาร
C26: (______________________)
C27: KOCH

Sheet 6
F2: KOCH PACKAGING AND PACKING SERVICES
D4: Package Label
D6: Shipper : | E6: KOCH | F6: Ship To : | G6: Mazda (MST) | H6: Package No. : | J6: =D14&"-"&E14&"-"&"001" -> 229530-6-001
C8: Supplier Code : | E8: KT076 | F8: Invoice No. : | G8: ='5'!G8 -> 11726091882
C10: Supplier Name: | E10: THAI KOITO CO.,LTD.
B13: No. | C13: Rack No | D13: PO. No. | E13: Line | F13: Part No. | G13: Part Name | H13: Invoice QTY. | I13: Dom QTY. | J13: Exp QTY. | K13: Delivery QTY | L13: Remark
B14: 1 | C14: 371 | D14: 229530 | E14: 6 | F14: DB7A51150B | G14: LAMP(R),RR COMB. | H14: 21 | I14: =H14 -> 21 | K14: =I14 -> 21 | L14: ="8B5"&"/"&C14 -> 8B5/371
B22: Total | K22: =SUM(K14:K21) -> 21
C24: ลงชื่อผู้ออกเอกสาร
C26: (______________________)
C27: KOCH

Sheet 7
F2: KOCH PACKAGING AND PACKING SERVICES
D4: Package Label
D6: Shipper : | E6: KOCH | F6: Ship To : | G6: Mazda (MST) | H6: Package No. : | J6: =D14&"-"&E14&"-"&"001" -> 229530-23-001
C8: Supplier Code : | E8: KT076 | F8: Invoice No. : | G8: ='6'!G8 -> 11726091882
C10: Supplier Name: | E10: THAI KOITO CO.,LTD.
B13: No. | C13: Rack No | D13: PO. No. | E13: Line | F13: Part No. | G13: Part Name | H13: Invoice QTY. | I13: Dom QTY. | J13: Exp QTY. | K13: Delivery QTY | L13: Remark
B14: 1 | C14: 125 | D14: 229530 | E14: 23 | F14: UL4J51160A | G14: LAMP(L),RR COMB. | H14: 33 | I14: =H14 -> 33 | K14: =I14 -> 33 | L14: ="8B5"&"/"&C14 -> 8B5/125
B22: Total | K22: =SUM(K14:K21) -> 33
C24: ลงชื่อผู้ออกเอกสาร
C26: (______________________)
C27: KOCH

Sheet 8
F2: KOCH PACKAGING AND PACKING SERVICES
D4: Package Label
D6: Shipper : | E6: KOCH | F6: Ship To : | G6: Mazda (MST) | H6: Package No. : | J6: =D14&"-"&E14&"-"&"001" -> 229530-17-001
C8: Supplier Code : | E8: KT076 | F8: Invoice No. : | G8: ='7'!G8 -> 11726091882
C10: Supplier Name: | E10: THAI KOITO CO.,LTD.
B13: No. | C13: Rack No | D13: PO. No. | E13: Line | F13: Part No. | G13: Part Name | H13: Invoice QTY. | I13: Dom QTY. | J13: Exp QTY. | K13: Delivery QTY | L13: Remark
B14: 1 | C14: 170 | D14: 229530 | E14: 17 | F14: UC2B51250B | G14: LAMP(L),BACK UP | H14: 96 | I14: =H14 -> 96 | K14: =I14 -> 96 | L14: ="8B5"&"/"&C14 -> 8B5/170
B15: 2 | C15: 170 | D15: 229530 | E15: 25 | F15: UL4L510K0B | G15: UNIT(R),HEAD LAMP | H15: 12 | I15: =H15 -> 12 | K15: =I15 -> 12 | L15: ="8B5"&"/"&C15 -> 8B5/170
B22: Total | K22: =SUM(K14:K21) -> 108
C24: ลงชื่อผู้ออกเอกสาร
C26: (______________________)
C27: KOCH

Sheet 9
F2: KOCH PACKAGING AND PACKING SERVICES
D4: Package Label
D6: Shipper : | E6: KOCH | F6: Ship To : | G6: Mazda (MST) | H6: Package No. : | J6: =D14&"-"&E14&"-"&"001" -> 229530-17-001
C8: Supplier Code : | E8: KT076 | F8: Invoice No. : | G8: ='8'!G8 -> 11726091882
C10: Supplier Name: | E10: THAI KOITO CO.,LTD.
B13: No. | C13: Rack No | D13: PO. No. | E13: Line | F13: Part No. | G13: Part Name | H13: Invoice QTY. | I13: Dom QTY. | J13: Exp QTY. | K13: Delivery QTY | L13: Remark
B14: 1 | C14: 235 | D14: 229530 | E14: 17 | F14: UC2B51250B | G14: LAMP(L),BACK UP | H14: 29 | I14: =H14 -> 29 | K14: =I14 -> 29 | L14: ="8B5"&"/"&C14 -> 8B5/235
B15: 2 | C15: 235 | D15: 229530 | E15: 25 | F15: UL4L510K0B | G15: UNIT(R),HEAD LAMP | H15: 12 | I15: =H15 -> 12 | K15: =I15 -> 12 | L15: ="8B5"&"/"&C15 -> 8B5/235
B22: Total | K22: =SUM(K14:K21) -> 41
C24: ลงชื่อผู้ออกเอกสาร
C26: (______________________)
C27: KOCH

Sheet 10
F2: KOCH PACKAGING AND PACKING SERVICES
D4: Package Label
D6: Shipper : | E6: KOCH | F6: Ship To : | G6: Mazda (MST) | H6: Package No. : | J6: =D14&"-"&E14&"-"&"001" -> 229530-6-001
C8: Supplier Code : | E8: KT076 | F8: Invoice No. : | G8: ='9'!G8 -> 11726091882
C10: Supplier Name: | E10: THAI KOITO CO.,LTD.
B13: No. | C13: Rack No | D13: PO. No. | E13: Line | F13: Part No. | G13: Part Name | H13: Invoice QTY. | I13: Dom QTY. | J13: Exp QTY. | K13: Delivery QTY | L13: Remark
B14: 1 | C14: 398 | D14: 229530 | E14: 6 | F14: DB7A51150B | G14: LAMP(R),RR COMB. | H14: 21 | I14: =H14 -> 21 | K14: =I14 -> 21 | L14: ="8B5"&"/"&C14 -> 8B5/398
B22: Total | K22: =SUM(K14:K21) -> 21
C24: ลงชื่อผู้ออกเอกสาร
C26: (______________________)
C27: KOCH

Sheet 11
F2: KOCH PACKAGING AND PACKING SERVICES
D4: Package Label
D6: Shipper : | E6: KOCH | F6: Ship To : | G6: Mazda (MST) | H6: Package No. : | J6: =D14&"-"&E14&"-"&"001" -> 229530-25-001
C8: Supplier Code : | E8: KT076 | F8: Invoice No. : | G8: ='10'!G8 -> 11726091882
C10: Supplier Name: | E10: THAI KOITO CO.,LTD.
B13: No. | C13: Rack No | D13: PO. No. | E13: Line | F13: Part No. | G13: Part Name | H13: Invoice QTY. | I13: Dom QTY. | J13: Exp QTY. | K13: Delivery QTY | L13: Remark
B14: 1 | C14: 501 | D14: 229530 | E14: 25 | F14: UL4L510K0B | G14: UNIT(R),HEAD LAMP | H14: 12 | I14: =H14 -> 12 | K14: =I14 -> 12 | L14: ="8B5"&"/"&C14 -> 8B5/501
B22: Total | K22: =SUM(K14:K21) -> 12
C24: ลงชื่อผู้ออกเอกสาร
C26: (______________________)
C27: KOCH

Sheet 12
F2: KOCH PACKAGING AND PACKING SERVICES
D4: Package Label
D6: Shipper : | E6: KOCH | F6: Ship To : | G6: Mazda (MST) | H6: Package No. : | J6: =D14&"-"&E14&"-"&"001" -> 229530-25-001
C8: Supplier Code : | E8: KT076 | F8: Invoice No. : | G8: ='10'!G8 -> 11726091882
C10: Supplier Name: | E10: THAI KOITO CO.,LTD.
B13: No. | C13: Rack No | D13: PO. No. | E13: Line | F13: Part No. | G13: Part Name | H13: Invoice QTY. | I13: Dom QTY. | J13: Exp QTY. | K13: Delivery QTY | L13: Remark
B14: 1 | C14: 373 | D14: 229530 | E14: 25 | F14: UL4L510K0B | G14: UNIT(R),HEAD LAMP | H14: 9 | I14: =H14 -> 9 | K14: =I14 -> 9 | L14: ="8B5"&"/"&C14 -> 8B5/373
B15: 2 | C15: 373 | D15: 229530 | E15: 28 | F15: UM4751070A | G15: LAMP(L),FRT. COMB. | H15: 5 | I15: =H15 -> 5 | K15: =I15 -> 5 | L15: ="8B5"&"/"&C15 -> 8B5/373
B16: 3 | C16: 373 | D16: 229530 | E16: 9 | F16: DB7A513G0C | G16: LAMP(L),TRUNK LID | H16: 17 | I16: =H16 -> 17 | K16: =I16 -> 17 | L16: ="8B5"&"/"&C16 -> 8B5/373
B22: Total | K22: =SUM(K14:K21) -> 31
C24: ลงชื่อผู้ออกเอกสาร
C26: (______________________)
C27: KOCH

Sheet 13
F2: KOCH PACKAGING AND PACKING SERVICES
D4: Package Label
D6: Shipper : | E6: KOCH | F6: Ship To : | G6: Mazda (MST) | H6: Package No. : | J6: =D14&"-"&E14&"-"&"001" -> 229530-9-001
C8: Supplier Code : | E8: KT076 | F8: Invoice No. : | G8: ='10'!G8 -> 11726091882
C10: Supplier Name: | E10: THAI KOITO CO.,LTD.
B13: No. | C13: Rack No | D13: PO. No. | E13: Line | F13: Part No. | G13: Part Name | H13: Invoice QTY. | I13: Dom QTY. | J13: Exp QTY. | K13: Delivery QTY | L13: Remark
B14: 1 | C14: 364 | D14: 229530 | E14: 9 | F14: DB7A513G0C | G14: LAMP(L),TRUNK LID | H14: 66 | I14: =H14 -> 66 | K14: =I14 -> 66 | L14: ="8B5"&"/"&C14 -> 8B5/364
B15: 2 | C15: 364 | D15: 229530 | E15: 18 | F15: UC2H51160A | G15: LAMP(L),RR COMB. | H15: 9 | I15: =H15 -> 9 | K15: =I15 -> 9 | L15: ="8B5"&"/"&C15 -> 8B5/364
B22: Total | K22: =SUM(K14:K21) -> 75
C24: ลงชื่อผู้ออกเอกสาร
C26: (______________________)
C27: KOCH

Sheet 14
F2: KOCH PACKAGING AND PACKING SERVICES
D4: Package Label
D6: Shipper : | E6: KOCH | F6: Ship To : | G6: Mazda (MST) | H6: Package No. : | J6: =D14&"-"&E14&"-"&"001" -> 229530-18-001
C8: Supplier Code : | E8: KT076 | F8: Invoice No. : | G8: ='10'!G8 -> 11726091882
C10: Supplier Name: | E10: THAI KOITO CO.,LTD.
B13: No. | C13: Rack No | D13: PO. No. | E13: Line | F13: Part No. | G13: Part Name | H13: Invoice QTY. | I13: Dom QTY. | J13: Exp QTY. | K13: Delivery QTY | L13: Remark
B14: 1 | C14: 507 | D14: 229530 | E14: 18 | F14: UC2H51160A | G14: LAMP(L),RR COMB. | H14: 33 | I14: =H14 -> 33 | K14: =I14 -> 33 | L14: ="8B5"&"/"&C14 -> 8B5/507
B22: Total | K22: =SUM(K14:K21) -> 33
C24: ลงชื่อผู้ออกเอกสาร
C26: (______________________)
C27: KOCH

Sheet เลือกปริ้นที่ล่ะ Rack no
F2: KOCH PACKAGING AND PACKING SERVICES
D4: Package Label
D6: Shipper : | E6: KOCH | F6: Ship To : | G6: Mazda (MST) | H6: Package No. : | J6: =D14&"-"&E14&"-"&"001" -> 229530-6-001
C8: Supplier Code : | E8: KT076 | F8: Invoice No. : | G8: ='10'!G8 -> 11726091882
C10: Supplier Name: | E10: THAI KOITO CO.,LTD.
B13: No. | C13: Rack No | D13: PO. No. | E13: Line | F13: Part No. | G13: Part Name | H13: Invoice QTY. | I13: Dom QTY. | J13: Exp QTY. | K13: Delivery QTY | L13: Remark
B14: 1 | C14: 201 | D14: 229530 | E14: 6 | F14: DB7A51150B | G14: LAMP(R),RR COMB. | H14: 21 | I14: =H14 -> 21 | K14: =I14 -> 21 | L14: ="8B5"&"/"&C14 -> 8B5/201
B15: 2 | C15: 290 | D15: 229530 | E15: 19 | F15: UC2J510K0B | G15: UNIT(R),HEAD LAMP | H15: 12 | I15: =H15 -> 12 | K15: =I15 -> 12 | L15: ="8B5"&"/"&C15 -> 8B5/290
B16: 3 | C16: 296 | D16: 229530 | E16: 4 | F16: DA6A513F0B | G16: LAMP(R),TRUNK LID | H16: 30 | I16: =H16 -> 30 | K16: =I16 -> 30 | L16: ="8B5"&"/"&C16 -> 8B5/296
B17: 4 | C17: 296 | D17: 229530 | E17: 3 | F17: D43N51160B | G17: LAMP(L),RR COMB. | H17: 15 | I17: =H17 -> 15 | K17: =I17 -> 15 | L17: ="8B5"&"/"&C17 -> 8B5/296
B18: 5 | C18: 296 | D18: 229530 | E18: 3 | F18: UL4H510K0B | G18: UNIT(R),HEAD LAMP | H18: 2 | I18: =H18 -> 2 | K18: =I18 -> 2 | L18: ="8B5"&"/"&C18 -> 8B5/296
B19: 6 | C19: 297 | D19: 229530 | E19: 26 | F19: UL4M510K0B | G19: UNIT(R),HEAD LAMP | H19: 12 | I19: =H19 -> 12 | K19: =I19 -> 12 | L19: ="8B5"&"/"&C19 -> 8B5/297
B20: 7 | C20: 362 | D20: 229530 | E20: 6 | F20: DB7A51150B | G20: LAMP(R),RR COMB. | H20: 21 | I20: =H20 -> 21 | K20: =I20 -> 21 | L20: ="8B5"&"/"&C20 -> 8B5/362
B21: 8 | C21: 371 | D21: 229530 | E21: 6 | F21: DB7A51150B | G21: LAMP(R),RR COMB. | H21: 21 | I21: =H21 -> 21 | K21: =I21 -> 21 | L21: ="8B5"&"/"&C21 -> 8B5/371
B22: 9 | C22: 125 | D22: 229530 | E22: 23 | F22: UL4J51160A | G22: LAMP(L),RR COMB. | H22: 33 | I22: =H22 -> 33 | K22: =I22 -> 33 | L22: ="8B5"&"/"&C22 -> 8B5/125
B23: 10 | C23: 170 | D23: 229530 | E23: 17 | F23: UC2B51250B | G23: LAMP(L),BACK UP | H23: 96 | I23: =H23 -> 96 | K23: =I23 -> 96 | L23: ="8B5"&"/"&C23 -> 8B5/170
B24: 11 | C24: 170 | D24: 229530 | E24: 25 | F24: UL4L510K0B | G24: UNIT(R),HEAD LAMP | H24: 12 | I24: =H24 -> 12 | K24: =I24 -> 12 | L24: ="8B5"&"/"&C24 -> 8B5/170
B25: 12 | C25: 235 | D25: 229530 | E25: 17 | F25: UC2B51250B | G25: LAMP(L),BACK UP | H25: 29 | I25: =H25 -> 29 | K25: =I25 -> 29 | L25: ="8B5"&"/"&C25 -> 8B5/235
... B39: 26 | C39: 273 | D39: 229530 | E39: 1 | F39: D09K51150D | G39: LAMP(R),RR COMB. | H39: 12 | I39: =H39 -> 12 | K39: =I39 -> 12 | L39: ="8B5"&"/"&C39 -> 8B5/273
B40: 27 | C40: 004 | D40: 229530 | E40: 23 | F40: UL4J51160A | G40: LAMP(L),RR COMB. | H40: 33 | I40: =H40 -> 33 | K40: =I40 -> 33 | L40: ="8B5"&"/"&C40 -> 8B5/004
B41: 28 | C41: 339 | D41: 229530 | E41: 23 | F41: UL4J51160A | G41: LAMP(L),RR COMB. | H41: 6 | I41: =H41 -> 6 | K41: =I41 -> 6 | L41: ="8B5"&"/"&C41 -> 8B5/339
B42: 29 | C42: 339 | D42: 229530 | E42: 8 | F42: DB7A513F0C | G42: LAMP(R),TRUNK LID | H42: 44 | I42: =H42 -> 44 | K42: =I42 -> 44 | L42: ="8B5"&"/"&C42 -> 8B5/339
B43: 30 | C43: 480 | D43: 229530 | E43: 23 | F43: UL4J51160A | G43: LAMP(L),RR COMB. | H43: 33 | I43: =H43 -> 33 | K43: =I43 -> 33 | L43: ="8B5"&"/"&C43 -> 8B5/480
B44: 31 | C44: 092 | D44: 229530 | E44: 6 | F44: DB7A51150B | G44: LAMP(R),RR COMB. | H44: 21 | I44: =H44 -> 21 | K44: =I44 -> 21 | L44: ="8B5"&"/"&C44 -> 8B5/092
B45: 32 | C45: 662 | D45: 229530 | E45: 22 | F45: UL4J51150A | G45: LAMP(R),RR COMB. | H45: 20 | I45: =H45 -> 20 | K45: =I45 -> 20 | L45: ="8B5"&"/"&C45 -> 8B5/662
B46: 33 | C46: 662 | D46: 229530 | E46: 19 | F46: UC2J510K0B | G46: UNIT(R),HEAD LAMP | H46: 2 | I46: =H46 -> 2 | K46: =I46 -> 2 | L46: ="8B5"&"/"&C46 -> 8B5/662
B47: 34 | C47: 662 | D47: 229530 | E47: 13 | F47: DN2151684 | G47: BRACKET(R),F.FOG LAM | H47: 10 | I47: =H47 -> 10 | K47: =I47 -> 10 | L47: ="8B5"&"/"&C47 -> 8B5/662
B48: 35 | C48: 662 | D48: 229530 | E48: 29 | F48: DL3351684A | G48: BRACKET(R),F.FOG LAM | H48: 5 | I48: =H48 -> 5 | K48: =I48 -> 5 | L48: ="8B5"&"/"&C48 -> 8B5/662
B49: 36 | C49: 493 | D49: 229530 | E49: 22 | F49: UL4J51150A | G49: LAMP(R),RR COMB. | H49: 33 | I49: =H49 -> 33 | K49: =I49 -> 33 | L49: ="8B5"&"/"&C49 -> 8B5/493
B50: 37 | C50: 566 | D50: 229530 | E50: 6 | F50: DB7A51150B | G50: LAMP(R),RR COMB. | H50: 21 | I50: =H50 -> 21 | K50: =I50 -> 21 | L50: ="8B5"&"/"&C50 -> 8B5/566
B51: 38 | C51: 426 | D51: 229530 | E51: 1 | F51: D09K51150D | G51: LAMP(R),RR COMB. | H51: 33 | I51: =H51 -> 33 | K51: =I51 -> 33 | L51: ="8B5"&"/"&C51 -> 8B5/426
B52: 39 | C52: 500 | D52: 229530 | E52: 19 | F52: UC2J510K0B | G52: UNIT(R),HEAD LAMP | H52: 12 | I52: =H52 -> 12 | K52: =I52 -> 12 | L52: ="8B5"&"/"&C52 -> 8B5/500
B53: 40 | C53: 382 | D53: 229530 | E53: 19 | F53: UC2J510K0B | G53: UNIT(R),HEAD LAMP | H53: 12 | I53: =H53 -> 12 | K53: =I53 -> 12 | L53: ="8B5"&"/"&C53 -> 8B5/382
B54: 41 | C54: 382 | D54: 229530 | E54: 16 | F54: UC2B51240B | G54: LAMP,BACK UP. | H54: 81 | I54: =H54 -> 81 | K54: =I54 -> 81 | L54: ="8B5"&"/"&C54 -> 8B5/382
B55: 42 | C55: 077 | D55: 229530 | E55: 19 | F55: UC2J510K0B | G55: UNIT(R),HEAD LAMP | H55: 12 | I55: =H55 -> 12 | K55: =I55 -> 12 | L55: ="8B5"&"/"&C55 -> 8B5/077
B56: 43 | C56: 077 | D56: 229530 | E56: 16 | F56: UC2B51240B | G56: LAMP,BACK UP. | H56: 84 | I56: =H56 -> 84 | K56: =I56 -> 84 | L56: ="8B5"&"/"&C56 -> 8B5/077
B57: 44 | C57: 171 | D57: 229530 | E57: 2 | F57: D09K51160D | G57: LAMP(L),RR COMB. | H57: 30 | I57: =H57 -> 30 | K57: =I57 -> 30 | L57: ="8B5"&"/"&C57 -> 8B5/171
B58: 45 | C58: 213 | D58: 229530 | E58: 2 | F58: D09K51160D | G58: LAMP(L),RR COMB. | H58: 5 | I58: =H58 -> 5 | K58: =I58 -> 5 | L58: ="8B5"&"/"&C58 -> 8B5/213
B59: 46 | C59: 213 | D59: 229530 | E59: 15 | F59: UC2B51150A | G59: LAMP(R),RR COMB. | H59: 26 | I59: =H59 -> 26 | K59: =I59 -> 26 | L59: ="8B5"&"/"&C59 -> 8B5/213
B60: 47 | C60: 565 | D60: 229530 | E60: 26 | F60: UL4M510K0B | G60: UNIT(R),HEAD LAMP | H60: 3 | I60: =H60 -> 3 | K60: =I60 -> 3 | L60: ="8B5"&"/"&C60 -> 8B5/565
...

Sheet  BP Delivery 280926
A1: No | B1: Rack No | C1: Part scan | D1: Part INV | E1: Part name | F1: Q'ty | G1: PO | H1: Line | I1: Invioce
A2: 1 | B2: 125 | C2: UL4J51160AB | D2: UL4J51160A | E2: LAMP(L),RR COMB. | F2: 1 | G2: 229530 | H2: 23 | I2: 11726091882 | L2: Sum of Q'ty
A3: 2 | B3: 125 | C3: UL4J51160AB | D3: UL4J51160A | E3: LAMP(L),RR COMB. | F3: 1 | G3: 229530 | H3: 23 | I3: 11726091882 | L3: Invioce | M3: Rack No | N3: PO | O3: Line | P3: Part INV | Q3: Part name | R3: Total
A4: 3 | B4: 125 | C4: UL4J51160AB | D4: UL4J51160A | E4: LAMP(L),RR COMB. | F4: 1 | G4: 229530 | H4: 23 | I4: 11726091882 | L4: 11726091882 | M4: 201 | N4: 229530 | O4: 6 | P4: DB7A51150B | Q4: LAMP(R),RR COMB. | R4: 21
A5: 4 | B5: 125 | C5: UL4J51160AB | D5: UL4J51160A | E5: LAMP(L),RR COMB. | F5: 1 | G5: 229530 | H5: 23 | I5: 11726091882 | L5: 11726091882 | M5: 290 | N5: 229530 | O5: 19 | P5: UC2J510K0B | Q5: UNIT(R),HEAD LAMP | R5: 12
A6: 5 | B6: 125 | C6: UL4J51160AB | D6: UL4J51160A | E6: LAMP(L),RR COMB. | F6: 1 | G6: 229530 | H6: 23 | I6: 11726091882 | L6: 11726091882 | M6: 296 | N6: 229530 | O6: 4 | P6: DA6A513F0B | Q6: LAMP(R),TRUNK LID | R6: 30
A7: 6 | B7: 125 | C7: UL4J51160AB | D7: UL4J51160A | E7: LAMP(L),RR COMB. | F7: 1 | G7: 229530 | H7: 23 | I7: 11726091882 | L7: 11726091882 | M7: 296 | N7: 229530 | O7: 3 | P7: D43N51160B | Q7: LAMP(L),RR COMB. | R7: 15
A8: 7 | B8: 125 | C8: UL4J51160AB | D8: UL4J51160A | E8: LAMP(L),RR COMB. | F8: 1 | G8: 229530 | H8: 23 | I8: 11726091882 | L8: 11726091882 | M8: 296 | N8: 229530 | O8: 3 | P8: UL4H510K0B | Q8: UNIT(R),HEAD LAMP | R8: 2
A9: 8 | B9: 125 | C9: UL4J51160AB | D9: UL4J51160A | E9: LAMP(L),RR COMB. | F9: 1 | G9: 229530 | H9: 23 | I9: 11726091882 | L9: 11726091882 | M9: 297 | N9: 229530 | O9: 26 | P9: UL4M510K0B | Q9: UNIT(R),HEAD LAMP | R9: 12
A10: 9 | B10: 125 | C10: UL4J51160AB | D10: UL4J51160A | E10: LAMP(L),RR COMB. | F10: 1 | G10: 229530 | H10: 23 | I10: 11726091882 | L10: 11726091882 | M10: 362 | N10: 229530 | O10: 6 | P10: DB7A51150B | Q10: LAMP(R),RR COMB. | R10: 21
A11: 10 | B11: 125 | C11: UL4J51160AB | D11: UL4J51160A | E11: LAMP(L),RR COMB. | F11: 1 | G11: 229530 | H11: 23 | I11: 11726091882 | L11: 11726091882 | M11: 371 | N11: 229530 | O11: 6 | P11: DB7A51150B | Q11: LAMP(R),RR COMB. | R11: 21
A12: 11 | B12: 125 | C12: UL4J51160AB | D12: UL4J51160A | E12: LAMP(L),RR COMB. | F12: 1 | G12: 229530 | H12: 23 | I12: 11726091882 | L12: 11726091882 | M12: 125 | N12: 229530 | O12: 23 | P12: UL4J51160A | Q12: LAMP(L),RR COMB. | R12: 33
A13: 12 | B13: 125 | C13: UL4J51160AB | D13: UL4J51160A | E13: LAMP(L),RR COMB. | F13: 1 | G13: 229530 | H13: 23 | I13: 11726091882 | L13: 11726091882 | M13: 170 | N13: 229530 | O13: 17 | P13: UC2B51250B | Q13: LAMP(L),BACK UP | R13: 96
A14: 13 | B14: 125 | C14: UL4J51160AB | D14: UL4J51160A | E14: LAMP(L),RR COMB. | F14: 1 | G14: 229530 | H14: 23 | I14: 11726091882 | L14: 11726091882 | M14: 170 | N14: 229530 | O14: 25 | P14: UL4L510K0B | Q14: UNIT(R),HEAD LAMP | R14: 12
A15: 14 | B15: 125 | C15: UL4J51160AB | D15: UL4J51160A | E15: LAMP(L),RR COMB. | F15: 1 | G15: 229530 | H15: 23 | I15: 11726091882 | L15: 11726091882 | M15: 235 | N15: 229530 | O15: 17 | P15: UC2B51250B | Q15: LAMP(L),BACK UP | R15: 29
... A29: 28 | B29: 125 | C29: UL4J51160AB | D29: UL4J51160A | E29: LAMP(L),RR COMB. | F29: 1 | G29: 229530 | H29: 23 | I29: 11726091882 | L29: 11726091882 | M29: 273 | N29: 229530 | O29: 1 | P29: D09K51150D | Q29: LAMP(R),RR COMB. | R29: 12
A30: 29 | B30: 125 | C30: UL4J51160AB | D30: UL4J51160A | E30: LAMP(L),RR COMB. | F30: 1 | G30: 229530 | H30: 23 | I30: 11726091882 | L30: 11726091882 | M30: 004 | N30: 229530 | O30: 23 | P30: UL4J51160A | Q30: LAMP(L),RR COMB. | R30: 33
A31: 30 | B31: 125 | C31: UL4J51160AB | D31: UL4J51160A | E31: LAMP(L),RR COMB. | F31: 1 | G31: 229530 | H31: 23 | I31: 11726091882 | L31: 11726091882 | M31: 339 | N31: 229530 | O31: 23 | P31: UL4J51160A | Q31: LAMP(L),RR COMB. | R31: 6
A32: 31 | B32: 125 | C32: UL4J51160AB | D32: UL4J51160A | E32: LAMP(L),RR COMB. | F32: 1 | G32: 229530 | H32: 23 | I32: 11726091882 | L32: 11726091882 | M32: 339 | N32: 229530 | O32: 8 | P32: DB7A513F0C | Q32: LAMP(R),TRUNK LID | R32: 44
A33: 32 | B33: 125 | C33: UL4J51160AB | D33: UL4J51160A | E33: LAMP(L),RR COMB. | F33: 1 | G33: 229530 | H33: 23 | I33: 11726091882 | L33: 11726091882 | M33: 480 | N33: 229530 | O33: 23 | P33: UL4J51160A | Q33: LAMP(L),RR COMB. | R33: 33
A34: 33 | B34: 125 | C34: UL4J51160AB | D34: UL4J51160A | E34: LAMP(L),RR COMB. | F34: 1 | G34: 229530 | H34: 23 | I34: 11726091882 | L34: 11726091882 | M34: 092 | N34: 229530 | O34: 6 | P34: DB7A51150B | Q34: LAMP(R),RR COMB. | R34: 21
A35: 1 | B35: 170 | C35: UC2B51250B- | D35: UC2B51250B | E35: LAMP(L),BACK UP | F35: 1 | G35: 229530 | H35: 17 | I35: 11726091882 | L35: 11726091882 | M35: 662 | N35: 229530 | O35: 22 | P35: UL4J51150A | Q35: LAMP(R),RR COMB. | R35: 20
A36: 2 | B36: 170 | C36: UC2B51250B- | D36: UC2B51250B | E36: LAMP(L),BACK UP | F36: 1 | G36: 229530 | H36: 17 | I36: 11726091882 | L36: 11726091882 | M36: 662 | N36: 229530 | O36: 19 | P36: UC2J510K0B | Q36: UNIT(R),HEAD LAMP | R36: 2
A37: 3 | B37: 170 | C37: UC2B51250B- | D37: UC2B51250B | E37: LAMP(L),BACK UP | F37: 1 | G37: 229530 | H37: 17 | I37: 11726091882 | L37: 11726091882 | M37: 662 | N37: 229530 | O37: 13 | P37: DN2151684 | Q37: BRACKET(R),F.FOG LAM | R37: 10
A38: 4 | B38: 170 | C38: UC2B51250B- | D38: UC2B51250B | E38: LAMP(L),BACK UP | F38: 1 | G38: 229530 | H38: 17 | I38: 11726091882 | L38: 11726091882 | M38: 662 | N38: 229530 | O38: 29 | P38: DL3351684A | Q38: BRACKET(R),F.FOG LAM | R38: 5
A39: 5 | B39: 170 | C39: UC2B51250B- | D39: UC2B51250B | E39: LAMP(L),BACK UP | F39: 1 | G39: 229530 | H39: 17 | I39: 11726091882 | L39: 11726091882 | M39: 493 | N39: 229530 | O39: 22 | P39: UL4J51150A | Q39: LAMP(R),RR COMB. | R39: 33
A40: 6 | B40: 170 | C40: UC2B51250B- | D40: UC2B51250B | E40: LAMP(L),BACK UP | F40: 1 | G40: 229530 | H40: 17 | I40: 11726091882 | L40: 11726091882 | M40: 566 | N40: 229530 | O40: 6 | P40: DB7A51150B | Q40: LAMP(R),RR COMB. | R40: 21
A41: 7 | B41: 170 | C41: UC2B51250B- | D41: UC2B51250B | E41: LAMP(L),BACK UP | F41: 1 | G41: 229530 | H41: 17 | I41: 11726091882 | L41: 11726091882 | M41: 426 | N41: 229530 | O41: 1 | P41: D09K51150D | Q41: LAMP(R),RR COMB. | R41: 33
A42: 8 | B42: 170 | C42: UC2B51250B- | D42: UC2B51250B | E42: LAMP(L),BACK UP | F42: 1 | G42: 229530 | H42: 17 | I42: 11726091882 | L42: 11726091882 | M42: 500 | N42: 229530 | O42: 19 | P42: UC2J510K0B | Q42: UNIT(R),HEAD LAMP | R42: 12
A43: 9 | B43: 170 | C43: UC2B51250B- | D43: UC2B51250B | E43: LAMP(L),BACK UP | F43: 1 | G43: 229530 | H43: 17 | I43: 11726091882 | L43: 11726091882 | M43: 382 | N43: 229530 | O43: 19 | P43: UC2J510K0B | Q43: UNIT(R),HEAD LAMP | R43: 12
A44: 10 | B44: 170 | C44: UC2B51250B- | D44: UC2B51250B | E44: LAMP(L),BACK UP | F44: 1 | G44: 229530 | H44: 17 | I44: 11726091882 | L44: 11726091882 | M44: 382 | N44: 229530 | O44: 16 | P44: UC2B51240B | Q44: LAMP,BACK UP. | R44: 81
A45: 11 | B45: 170 | C45: UC2B51250B- | D45: UC2B51250B | E45: LAMP(L),BACK UP | F45: 1 | G45: 229530 | H45: 17 | I45: 11726091882 | L45: 11726091882 | M45: 077 | N45: 229530 | O45: 19 | P45: UC2J510K0B | Q45: UNIT(R),HEAD LAMP | R45: 12
A46: 12 | B46: 170 | C46: UC2B51250B- | D46: UC2B51250B | E46: LAMP(L),BACK UP | F46: 1 | G46: 229530 | H46: 17 | I46: 11726091882 | L46: 11726091882 | M46: 077 | N46: 229530 | O46: 16 | P46: UC2B51240B | Q46: LAMP,BACK UP. | R46: 84
A47: 13 | B47: 170 | C47: UC2B51250B- | D47: UC2B51250B | E47: LAMP(L),BACK UP | F47: 1 | G47: 229530 | H47: 17 | I47: 11726091882 | L47: 11726091882 | M47: 171 | N47: 229530 | O47: 2 | P47: D09K51160D | Q47: LAMP(L),RR COMB. | R47: 30
A48: 14 | B48: 170 | C48: UC2B51250B- | D48: UC2B51250B | E48: LAMP(L),BACK UP | F48: 1 | G48: 229530 | H48: 17 | I48: 11726091882 | L48: 11726091882 | M48: 213 | N48: 229530 | O48: 2 | P48: D09K51160D | Q48: LAMP(L),RR COMB. | R48: 5
A49: 15 | B49: 170 | C49: UC2B51250B- | D49: UC2B51250B | E49: LAMP(L),BACK UP | F49: 1 | G49: 229530 | H49: 17 | I49: 11726091882 | L49: 11726091882 | M49: 213 | N49: 229530 | O49: 15 | P49: UC2B51150A | Q49: LAMP(R),RR COMB. | R49: 26
A50: 16 | B50: 170 | C50: UC2B51250B- | D50: UC2B51250B | E50: LAMP(L),BACK UP | F50: 1 | G50: 229530 | H50: 17 | I50: 11726091882 | L50: 11726091882 | M50: 565 | N50: 229530 | O50: 26 | P50: UL4M510K0B | Q50: UNIT(R),HEAD LAMP | R50: 3
A51: 17 | B51: 170 | C51: UC2B51250B- | D51: UC2B51250B | E51: LAMP(L),BACK UP | F51: 1 | G51: 229530 | H51: 17 | I51: 11726091882 | L51: 11726091882 | M51: 565 | N51: 229530 | O51: 5 | P51: DA6A513G0B | Q51: LAMP(L),TRUNK LID | R51: 30
A52: 18 | B52: 170 | C52: UC2B51250B- | D52: UC2B51250B | E52: LAMP(L),BACK UP | F52: 1 | G52: 229530 | H52: 17 | I52: 11726091882 | L52: 11726091882 | M52: 565 | N52: 229530 | O52: 27 | P52: UL4M510L0B | Q52: UNIT(L),HEAD LAMP | R52: 5
A53: 19 | B53: 170 | C53: UC2B51250B- | D53: UC2B51250B | E53: LAMP(L),BACK UP | F53: 1 | G53: 229530 | H53: 17 | I53: 11726091882 | L53: 11726091882 | M53: 565 | N53: 229530 | O53: 11 | P53: DB7A513J8 | Q53: GASKET(L),LAMP-TRUNK | R53: 20
...
